<?xml version="1.0" ?> <!-- Preface -->
<sdf version="1.9"> <!-- Preface -->
	<world name="sensing_rover_world"> <!-- World tag; everything else is nested here -->
    	<physics name="1ms" type="ode"> <!-- simulation physics definition-->
            <max_step_size>0.001</max_step_size> <!-- physics integration time step -->
            <real_time_factor>1.0</real_time_factor> 
        </physics>
        <!-- these plugins are required by the GUI-->
        <plugin
            filename="libignition-gazebo-physics-system"
            name="ignition::gazebo::systems::Physics">
        </plugin>
        <plugin
      filename="gz-sim-sensors-system"
      name="gz::sim::systems::Sensors">
      <render_engine>ogre2</render_engine>
    </plugin>
        <plugin
            filename="libignition-gazebo-user-commands-system"
            name="ignition::gazebo::systems::UserCommands">
        </plugin>
        <plugin
            filename="libignition-gazebo-scene-broadcaster-system"
            name="ignition::gazebo::systems::SceneBroadcaster">
        </plugin>

        
        <!-- Other plugins can be specified, depending on thge developer's need-->
    <!-- Lighting definition -->
	<light type="directional" name="sun"> 
    	<cast_shadows>true</cast_shadows>
    	<pose>0 0 10 0 0 0</pose>
  	    <diffuse>0.8 0.8 0.8 1</diffuse>
	    <specular>0.2 0.2 0.2 1</specular>
        <attenuation>
        	<range>1000</range>
            <constant>0.9</constant>
            <linear>0.01</linear>
        	<quadratic>0.001</quadratic>
     	</attenuation>
            <direction>-0.5 0.1 -0.9</direction>
 	</light>
    <!-- Ground plane definition. Modeling the ground = modelling the terrain-->
    <model name="ground_plane">
		<static>true</static>  <!-- if set to false, the ground will be falling-->
		<link name="link"> <!-- the ground is set as a link as well-->
			<collision name="collision"> 
				<geometry>  
					<plane> 
						<normal>0 0 1</normal>                
					</plane>        
				</geometry> 
			</collision> 
			<visual name="visual"> 
				<geometry>
                   	<plane>
                   		<normal>0 0 1</normal>
      	              	<size>100 100</size>
                    </plane>
                </geometry>
	            <material> 
            	<ambient>0.900 0.567 0.200 1</ambient>
                <diffuse>0.900 0.567 0.200 1</diffuse>
                <specular>0.2 0.2 0.2 1</specular>
	            </material>
            </visual>
        </link>
	</model> 

    <!-- Rover model definition -->

    <model name='rover' canonical_link='chassis'>
        <pose relative_to='world'>0 0 0 0 0 3.1416</pose>

        <link name='chassis'>
            <pose relative_to='__model__'>0 0 0.4 0 0 0</pose>
            <inertial> <!--inertial properties of the link mass, inertia matix-->
                <mass>1.14395</mass>
                <inertia>
                    <ixx>0.095329</ixx>
                    <ixy>0</ixy>
                    <ixz>0</ixz>
                    <iyy>0.381317</iyy>
                    <iyz>0</iyz>
                    <izz>0.476646</izz>
                </inertia>
            </inertial>
            <visual name='visual'>
                <geometry>
                    <box>
                        <size>2.0 1.0 0.5</size>
                    </box>
                </geometry>
                <!--let's add color to our link-->
                <material>
                    <ambient>0.2 0.2 0.2 1</ambient>
                    <diffuse>0.2 0.2 0.2 1</diffuse>
                    <specular>0.2 0.2 0.2 1</specular>
                    // Change the color of ambient and diffuse to green
                    <ambient>0.0 0.8 0.0 1</ambient>
                    <diffuse>0.0 0.8 0.0 1</diffuse>
                </material>
            </visual>
            <collision name='collision'>
                <geometry>
                    <box>
                        <size>2.0 1.0 0.5</size>
                    </box>
                </geometry>
            </collision>

            <!-- add a lidar   -->
            <sensor name='gpu_lidar' type='gpu_lidar'>
                <topic>lidar_topic</topic>
                <update_rate>10</update_rate>
                <pose relative_to='chassis'>0.5 0 0 0 0 0</pose>
                <lidar>
                    <scan>
                        <horizontal>
                            <samples>90</samples> <!-- Number of samples along the horizontal direction -->
                            <resolution>1</resolution>
                            <min_angle>-0.785398</min_angle> <!-- radians -->
                            <max_angle>0.785398</max_angle> <!-- radians -->
                        </horizontal>
                        <vertical>
                            <samples>1</samples> <!-- Number of samples along the vertical direction -->
                            <resolution>1</resolution>
                            <min_angle>0</min_angle> <!-- radians -->
                            <max_angle>0</max_angle> <!-- radians -->
                        </vertical>
                    </scan>
                    <range>
                        <min>0.08</min> <!-- meters -->
                        <max>10.0</max> <!-- meters -->
                        <resolution>0.01</resolution> 
                    </range>
                </lidar>
                <visualize>true</visualize>
            </sensor>
        <static>true</static>

        </link>

        <link name='left_wheel_rear'>
            <pose relative_to="chassis">-0.5 0.6 0 -1.5707 0 0</pose>
            <inertial>
                <mass>1</mass>
                <inertia>
                    <ixx>0.043333</ixx>
                    <ixy>0</ixy>
                    <ixz>0</ixz>
                    <iyy>0.043333</iyy>
                    <iyz>0</iyz>
                    <izz>0.08</izz>
                </inertia>
            </inertial>
            <visual name='visual'>
                <geometry>
                    <cylinder>
                        <radius>0.4</radius>
                        <length>0.2</length>
                    </cylinder>
                </geometry>
                <material>
                    <ambient>0.0 0.0 0.0 1</ambient>
                    <diffuse>0.0 0.0 0.0 1</diffuse>
                    <specular>0.0 0.0 0.0 1</specular>
                </material>
            </visual>
            <collision name='collision'>
                <geometry>
                    <cylinder>
                        <radius>0.4</radius>
                        <length>0.2</length>
                    </cylinder>
                </geometry>
            </collision>
        </link>
        <link name='right_wheel_rear'>
            <pose relative_to="chassis">-0.5 -0.6 0 -1.5707 0 0</pose> <!--angles are in radian-->
            <inertial>
                <mass>1</mass>
                <inertia>
                    <ixx>0.043333</ixx>
                    <ixy>0</ixy>
                    <ixz>0</ixz>
                    <iyy>0.043333</iyy>
                    <iyz>0</iyz>
                    <izz>0.08</izz>
                </inertia>
            </inertial>
            <visual name='visual'>
                <geometry>
                    <cylinder>
                        <radius>0.4</radius>
                        <length>0.2</length>
                    </cylinder>
                </geometry>
                <material>
                    <ambient>0.0 0.0 0.0 1</ambient>
                    <diffuse>0.0 0.0 0.0 1</diffuse>
                    <specular>0.0 0.0 0.0 1</specular>
                </material>
            </visual>
            <collision name='collision'>
                <geometry>
                    <cylinder>
                        <radius>0.4</radius>
                        <length>0.2</length>
                    </cylinder>
                </geometry>
            </collision>
        </link>
        <link name='left_wheel_front'>
            <pose relative_to="chassis">0.5 0.6 0 -1.5707 0 0</pose>
            <inertial>
                <mass>1</mass>
                <inertia>
                    <ixx>0.043333</ixx>
                    <ixy>0</ixy>
                    <ixz>0</ixz>
                    <iyy>0.043333</iyy>
                    <iyz>0</iyz>
                    <izz>0.08</izz>
                </inertia>
            </inertial>
            <visual name='visual'>
                <geometry>
                    <cylinder>
                        <radius>0.4</radius>
                        <length>0.2</length>
                    </cylinder>
                </geometry>
                <material>
                    <ambient>0.0 0.0 0.0 1</ambient>
                    <diffuse>0.0 0.0 0.0 1</diffuse>
                    <specular>0.0 0.0 0.0 1</specular>
                </material>
            </visual>
            <collision name='collision'>
                <geometry>
                    <cylinder>
                        <radius>0.4</radius>
                        <length>0.2</length>
                    </cylinder>
                </geometry>
            </collision>
        </link>
        <link name='right_wheel_front'>
            <pose relative_to="chassis">0.5 -0.6 0 -1.5707 0 0</pose> <!--angles are in radian-->
            <inertial>
                <mass>1</mass>
                <inertia>
                    <ixx>0.043333</ixx>
                    <ixy>0</ixy>
                    <ixz>0</ixz>
                    <iyy>0.043333</iyy>
                    <iyz>0</iyz>
                    <izz>0.08</izz>
                </inertia>
            </inertial>
            <visual name='visual'>
                <geometry>
                    <cylinder>
                        <radius>0.4</radius>
                        <length>0.2</length>
                    </cylinder>
                </geometry>
                <material>
                    <ambient>0.0 0.0 0.0 1</ambient>
                    <diffuse>0.0 0.0 0.0 1</diffuse>
                    <specular>0.0 0.0 0.0 1</specular>
                </material>
            </visual>
            <collision name='collision'>
                <geometry>
                    <cylinder>
                        <radius>0.4</radius>
                        <length>0.2</length>
                    </cylinder>
                </geometry>
            </collision>
        </link>

        <joint name='left_wheel_joint_rear' type='revolute'>
            <pose relative_to='left_wheel_rear'/>
            <parent>chassis</parent>
            <child>left_wheel_rear</child>
            <axis>
                <xyz expressed_in='__model__'>0 1 0</xyz>
                <limit>
                    <lower>-1.79769e+308</lower>
                    <upper>1.79769e+308</upper>
                </limit>
            </axis>
        </joint>

        <joint name='right_wheel_joint_rear' type='revolute'>
            <pose relative_to='right_wheel_rear'/>
            <parent>chassis</parent>
            <child>right_wheel_rear</child>
            <axis>
                <xyz expressed_in='__model__'>0 1 0</xyz>
                <limit>
                    <lower>-1.79769e+308</lower>
                    <upper>1.79769e+308</upper>
                </limit>
            </axis>
        </joint>

        <joint name='left_wheel_joint_front' type='revolute'>
            <pose relative_to='left_wheel_front'/>
            <parent>chassis</parent>
            <child>left_wheel_front</child>
            <axis>
                <xyz expressed_in='__model__'>0 1 0</xyz>
                <limit>
                    <lower>-1.79769e+308</lower>
                    <upper>1.79769e+308</upper>
                </limit>
            </axis>
        </joint>

        <joint name='right_wheel_joint_front' type='revolute'>
            <pose relative_to='right_wheel_front'/>
            <parent>chassis</parent>
            <child>right_wheel_front</child>
            <axis>
                <xyz expressed_in='__model__'>0 1 0</xyz>
                <limit>
                    <lower>-1.79769e+308</lower>
                    <upper>1.79769e+308</upper>
                </limit>
            </axis>
        </joint>


        <plugin
            filename="libignition-gazebo-diff-drive-system.so"
            name="ignition::gazebo::systems::DiffDrive">
            <left_joint>left_wheel_joint_rear</left_joint>
            <right_joint>right_wheel_joint_rear</right_joint>
            <left_joint>left_wheel_joint_front</left_joint>
            <right_joint>right_wheel_joint_front</right_joint>
            <wheel_separation>1.2</wheel_separation>
            <wheel_radius>0.4</wheel_radius>
            <odom_publish_frequency>1</odom_publish_frequency>
            <topic>rover_cmd_vel</topic>
        </plugin>

        <plugin
            filename="libignition-gazebo-pose-publisher-system.so"
            name="ignition::gazebo::systems::PosePublisher">
            <publish_link_pose>false</publish_link_pose>
			<publish_nested_model_pose>true</publish_nested_model_pose>
            <update_frequency>1</update_frequency> <!--Hz-->
        </plugin>

        <plugin
			filename="libignition-gazebo-joint-state-publisher-system"
			name="ignition::gazebo::systems::JointStatePublisher">
			<joint_name>right_wheel_joint_rear</joint_name>
            <joint_name>left_wheel_joint_rear</joint_name>
            <joint_name>right_wheel_joint_front</joint_name>
            <joint_name>left_wheel_joint_front</joint_name>         
            <frequency>1</frequency> 
			<topic>wheels_read</topic>
		</plugin>

    </model>

    <model name="lander" canonical_link="lander">
        <pose relative_to="world">-3.5 0 0 0 0 0</pose>
        <link name="lander">
            <collision name="lander_collision">
                <geometry>
                    <box>
                        <size>3 3 3</size>
                    </box>
                </geometry>
            </collision>
            <visual name="lander_visual">
                <geometry>
                    <box>
                        <size>3 3 3</size>
                    </box>
                </geometry>
                <material>
                    <ambient>0.5 0.5 0.5 1</ambient>
                    <diffuse>0.5 0.5 0.5 1</diffuse>
                    <specular>0.5 0.5 0.5 1</specular>
                </material>
            </visual>
        </link>
        <joint name="lander_joint" type="fixed">
            <parent>world</parent>
            <child>lander</child>
        </joint>
        
    </model>
    
   </world>
</sdf>
